
<?xml version="1.0" ?>

<sdf version="1.7">

    <model name="single_pendulum">
        <pose>0 0 0.2 0 0 0</pose>

        <link name='base_link'>
        <inertial>
            <pose>0 0 0 0 0 0</pose>
            <mass>100</mass>
            <inertia>
            <ixx>1</ixx>
            <ixy>0</ixy>
            <ixz>0</ixz>
            <iyy>1</iyy>
            <iyz>0</iyz>
            <izz>1</izz>
            </inertia>
        </inertial>
        <collision name='base_link_fixed_joint_lump__base_collision'>
            <pose>0 0 1 0 0 0</pose>
            <geometry>
            <box>
                <size>0.15 0.15 2.15</size>
            </box>
            </geometry>
        </collision>
        <visual name='base_link_fixed_joint_lump__base_visual'>
            <pose>0 0 1 0 0 0</pose>
            <geometry>
            <box>
                <size>0.15 0.15 2.15</size>
            </box>
            </geometry>
        </visual>
        </link>
        <joint name='upper_joint' type='revolute'>
        <pose relative_to='base_link'>0.15 0 2 -1.5708 0 0</pose>
        <parent>base_link</parent>
        <child>upper_link</child>
        <axis>
            <xyz>1 0 0</xyz>
            <limit>
            <lower>-5</lower>
            <upper>5</upper>
            <effort>100</effort>
            <velocity>100</velocity>
            </limit>
            <dynamics>
            <spring_reference>0</spring_reference>
            <spring_stiffness>0</spring_stiffness>
            </dynamics>
        </axis>
        </joint>
        <link name='upper_link'>
        <pose relative_to='upper_joint'>0 0 0 0 0 0</pose>
        <inertial>
            <pose>0 0 0.0.4 0 0 0</pose>
            <mass>1</mass>
            <inertia>
            <ixx>1</ixx>
            <ixy>0</ixy>
            <ixz>0</ixz>
            <iyy>1</iyy>
            <iyz>0</iyz>
            <izz>1</izz>
            </inertia>
        </inertial>
        <collision name='upper_link_collision'>
            <pose>0 0 0.0.4 0 0 0</pose>
            <geometry>
            <box>
                <size>0.15 0.15 0.9</size>
            </box>
            </geometry>
        </collision>
        <visual name='upper_link_visual'>
            <pose>0 0 0.375 0 0 0</pose>
            <geometry>
            <box>
                <size>0.15 0.15 0.9</size>
            </box>
            </geometry>
        </visual>
        </link>

        <frame name='fake_base_fixed_joint' attached_to='base_link'>
        <pose>0 0 0 0 0 0</pose>
        </frame>
        <frame name='base' attached_to='fake_base_fixed_joint'>
        <pose>0 0 0 0 0 0</pose>
        </frame>

        <!-- Launch the other YARP devices, in this case a controlBoard_nws_yarp to expose the controlboard functionalities via YARP ports -->
        <plugin name="gzyarp::ControlBoard" filename="gz-sim-yarp-controlboard-system">
            <yarpConfigurationFile>/home/acroci/repos/gz-sim-yarp-plugins/tutorial/models/single_pendulum/conf/gazebo_controlboard.ini</yarpConfigurationFile>
            <!-- <yarpConfigurationFile>model://single_pendulum/conf/gazebo_controlboard.ini</yarpConfigurationFile> -->
            <initialConfiguration>0.0 0.0</initialConfiguration>
        </plugin>
        <plugin name="gzyarp::RobotInterface" filename="gz-sim-yarp-robotinterface-system">
            <yarpRobotInterfaceConfigurationFile>/home/acroci/repos/gz-sim-yarp-plugins/tutorial/models/single_pendulum/conf/single_pendulum_nws.xml</yarpRobotInterfaceConfigurationFile>
            <!-- <yarpRobotInterfaceConfigurationFile>model://single_pendulum/conf/single_pendulum_nws.xml</yarpRobotInterfaceConfigurationFile> -->
        </plugin>
    </model>

</sdf>
