<?xml version="1.0" ?>

<sdf version="1.7">
  <world name="turorial_controlboard">
    <physics name="1ms" type="ignored">
      <max_step_size>0.001</max_step_size>
      <real_time_factor>1.0</real_time_factor>
    </physics>
    <plugin
      filename="gz-sim-physics-system"
      name="gz::sim::systems::Physics">
    </plugin>
    <plugin
      filename="gz-sim-user-commands-system"
      name="gz::sim::systems::UserCommands">
    </plugin>
    <plugin
      filename="gz-sim-sensors-system"
      name="gz::sim::systems::Sensors">
    </plugin>
    <plugin
      filename="gz-sim-scene-broadcaster-system"
      name="gz::sim::systems::SceneBroadcaster">
    </plugin>

    <light type="directional" name="sun">
      <cast_shadows>true</cast_shadows>
      <pose>0 0 10 0 0 0</pose>
      <diffuse>0.8 0.8 0.8 1</diffuse>
      <specular>0.2 0.2 0.2 1</specular>
      <attenuation>
        <range>1000</range>
        <constant>0.9</constant>
        <linear>0.01</linear>
        <quadratic>0.001</quadratic>
      </attenuation>
      <direction>-0.5 0.1 -0.9</direction>
    </light>

    <model name="ground_plane">
      <static>true</static>
      <link name="link">
        <collision name="collision">
          <geometry>
            <plane>
              <normal>0 0 1</normal>
              <size>100 100</size>
            </plane>
          </geometry>
        </collision>
        <visual name="visual">
          <geometry>
            <plane>
              <normal>0 0 1</normal>
              <size>100 100</size>
            </plane>
          </geometry>
          <material>
            <ambient>0.8 0.8 0.8 1</ambient>
            <diffuse>0.8 0.8 0.8 1</diffuse>
            <specular>0.8 0.8 0.8 1</specular>
          </material>
        </visual>
      </link>
    </model>

    <model name="single_pendulum">
      <pose>0 0 0.2 0 0 0</pose>

      <link name='base_link'>
        <inertial>
          <pose>0 0 0 0 0 0</pose>
          <mass>100</mass>
          <inertia>
            <ixx>1</ixx>
            <ixy>0</ixy>
            <ixz>0</ixz>
            <iyy>1</iyy>
            <iyz>0</iyz>
            <izz>1</izz>
          </inertia>
        </inertial>
        <collision name='base_link_fixed_joint_lump__base_collision'>
          <pose>0 0 1 0 0 0</pose>
          <geometry>
            <box>
              <size>0.14999999999999999 0.14999999999999999 2.1499999999999999</size>
            </box>
          </geometry>
        </collision>
        <visual name='base_link_fixed_joint_lump__base_visual'>
          <pose>0 0 1 0 0 0</pose>
          <geometry>
            <box>
              <size>0.14999999999999999 0.14999999999999999 2.1499999999999999</size>
            </box>
          </geometry>
        </visual>
      </link>
      <joint name='upper_joint' type='revolute'>
        <pose relative_to='base_link'>0.14999999999999999 0 2 -1.5708 0 0</pose>
        <parent>base_link</parent>
        <child>upper_link</child>
        <axis>
          <xyz>1 0 0</xyz>
          <limit>
            <lower>-5</lower>
            <upper>5</upper>
            <effort>100</effort>
            <velocity>100</velocity>
          </limit>
          <dynamics>
            <spring_reference>0</spring_reference>
            <spring_stiffness>0</spring_stiffness>
          </dynamics>
        </axis>
      </joint>
      <link name='upper_link'>
        <pose relative_to='upper_joint'>0 0 0 0 0 0</pose>
        <inertial>
          <pose>0 0 0.40000000000000002 0 0 0</pose>
          <mass>1</mass>
          <inertia>
            <ixx>1</ixx>
            <ixy>0</ixy>
            <ixz>0</ixz>
            <iyy>1</iyy>
            <iyz>0</iyz>
            <izz>1</izz>
          </inertia>
        </inertial>
        <collision name='upper_link_collision'>
          <pose>0 0 0.40000000000000002 0 0 0</pose>
          <geometry>
            <box>
              <size>0.14999999999999999 0.14999999999999999 0.90000000000000002</size>
            </box>
          </geometry>
        </collision>
        <visual name='upper_link_visual'>
          <pose>0 0 0.375 0 0 0</pose>
          <geometry>
            <box>
              <size>0.14999999999999999 0.14999999999999999 0.90000000000000002</size>
            </box>
          </geometry>
        </visual>
      </link>

      <frame name='fake_base_fixed_joint' attached_to='base_link'>
        <pose>0 0 0 0 0 0</pose>
      </frame>
      <frame name='base' attached_to='fake_base_fixed_joint'>
        <pose>0 0 0 0 0 0</pose>
      </frame>

      <!-- Launch the other YARP devices, in this case a controlBoard_nws_yarp to expose the controlboard functionalities via YARP ports -->
      <plugin name="gzyarp::ControlBoard" filename="gz-sim-yarp-controlboard-system">
          <yarpConfigurationFile>model://single_pendulum/conf/gazebo_controlboard.ini</yarpConfigurationFile>
          <initialConfiguration>0.0 0.0</initialConfiguration>
      </plugin>
      <plugin name="robotinterface" filename="libgazebo_yarp_robotinterface.so">
          <yarpRobotInterfaceConfigurationFile>model://single_pendulum/conf/single_pendulum_nws.xml</yarpRobotInterfaceConfigurationFile>
      </plugin>
    </model>
    
  </world>
</sdf>
